Workbook

Sheet MASTER_TERM_REGISTRY
A1: This is the only part I don't like. I love that it leans back, but I wish I could stop it from leaning back. Oh. I pushed it. I know I would never stop it. Well, I guess not. Let's see, hold on. I like these, these. I've watched this one video and they're like this is the the backs that you need to get. But it's not this one. Hello. OK, then OK. Try now and then tell me when you wanna stop weather. Oh yeah, yeah. It's like a. Oh yeah, yeah. OK. Now I get it. I've been really debating to get this type. I watch this one guy that. Apparently he knows a lot about chairs and. He said that these are the best. Yeah, he said. Yeah, yeah, I didn't either. But yeah, it was to him. Do you want to try for a bit? Yeah. OK. It worked out OK. Perch on the edge of that one. I mean, it's just a bad habit. This one. Well, another thing I like about this one is my arms are above the table. On that, on the chair that you're taking. My arms are here, so it's always like that. Like my arms 3. Yeah, it is. Works. | B1: category | C1: fruit_mapping | D1: tier | E1: weight | F1: dialect | G1: active | H1: subcategory | I1: source_sheets | J1: semantic_register | K1: belief_deriv_level | L1: six_needs_served | M1: polarity_stability | N1: ai_detection | O1: danger_level | P1: shibboleth_cluster
A2: wisdom | B2: WISDOM | F2: Standard_English | G2: Y | I2: WISDOM_TERMS | J2: Diluted_2025 | K2: Meaning | L2: Growth | M2: Stable | N2: N | O2: Low | P2: Pastoral
A3: discernment | B3: WISDOM | F3: Standard_English | G3: Y | I3: WISDOM_TERMS | J3: Diluted_2025 | K3: Meaning | L3: Growth | M3: Stable | N3: N | O3: Low | P3: Pastoral
A4: eternal | B4: WISDOM | F4: Standard_English | G4: Y | I4: WISDOM_TERMS | J4: Diluted_2025 | K4: Meaning | L4: Growth | M4: Stable | N4: N | O4: Low | P4: Pastoral
A5: transcend | B5: WISDOM | F5: Standard_English | G5: Y | I5: WISDOM_TERMS | J5: Diluted_2025 | K5: Meaning | L5: Growth | M5: Stable | N5: N | O5: Low | P5: Pastoral
A6: revelation | B6: WISDOM | F6: Standard_English | G6: Y | I6: WISDOM_TERMS | J6: Diluted_2025 | K6: Meaning | L6: Growth | M6: Stable | N6: N | O6: Low | P6: Pastoral
A7: mystery | B7: WISDOM | F7: Standard_English | G7: Y | I7: WISDOM_TERMS | J7: Diluted_2025 | K7: Meaning | L7: Growth | M7: Stable | N7: N | O7: Low | P7: Pastoral
A8: grace | B8: WISDOM | F8: Standard_English | G8: Y | I8: WISDOM_TERMS | J8: Diluted_2025 | K8: Meaning | L8: Growth | M8: Stable | N8: N | O8: Low | P8: Pastoral
A9: covenant | B9: WISDOM | F9: Standard_English | G9: Y | I9: WISDOM_TERMS | J9: Diluted_2025 | K9: Meaning | L9: Growth | M9: Stable | N9: N | O9: Low | P9: Pastoral
A10: truth | B10: WISDOM | F10: Standard_English | G10: Y | I10: WISDOM_TERMS | J10: Diluted_2025 | K10: Meaning | L10: Growth | M10: Stable | N10: N | O10: Low | P10: Pastoral
A11: logos | B11: WISDOM | F11: Standard_English | G11: Y | I11: WISDOM_TERMS | J11: Diluted_2025 | K11: Meaning | L11: Growth | M11: Stable | N11: N | O11: Low | P11: Pastoral
A12: spirit | B12: WISDOM | F12: Standard_English | G12: Y | I12: WISDOM_TERMS | J12: Diluted_2025 | K12: Meaning | L12: Growth | M12: Stable | N12: N | O12: Low | P12: Pastoral
A13: divine | B13: WISDOM | F13: Standard_English | G13: Y | I13: WISDOM_TERMS | J13: Diluted_2025 | K13: Meaning | L13: Growth | M13: Stable | N13: N | O13: Low | P13: Pastoral
... A128: however | B128: BRIDGE | F128: Standard_English | G128: Y | I128: BRIDGE_TERMS | J128: Standard | K128: Interpretation | L128: None | M128: Stable | N128: N | O128: Low | P128: None
A129: FALSE | B129: NEGATION | F129: Standard_English | G129: Y | I129: NEGATION_TERMS | J129: Standard | K129: Interpretation | L129: Multiple | M129: Stable | N129: N | O129: Low | P129: None
A130: can't | B130: NEGATION | F130: Standard_English | G130: Y | I130: NEGATION_TERMS | J130: Standard | K130: Interpretation | L130: Multiple | M130: Stable | N130: N | O130: Low | P130: None
A131: never | B131: NEGATION | F131: Standard_English | G131: Y | I131: NEGATION_TERMS | J131: Standard | K131: Interpretation | L131: Multiple | M131: Stable | N131: N | O131: High | P131: None
A132: fails | B132: NEGATION | F132: Standard_English | G132: Y | I132: NEGATION_TERMS | J132: Standard | K132: Interpretation | L132: Multiple | M132: Stable | N132: N | O132: Low | P132: None
A133: cannot | B133: NEGATION | F133: Standard_English | G133: Y | I133: NEGATION_TERMS | J133: Standard | K133: Interpretation | L133: Multiple | M133: Stable | N133: N | O133: Low | P133: None
A134: no | B134: NEGATION | F134: Standard_English | G134: Y | I134: NEGATION_TERMS | J134: Standard | K134: Interpretation | L134: Multiple | M134: Stable | N134: N | O134: Low | P134: None
A135: not | B135: NEGATION | F135: Standard_English | G135: Y | I135: NEGATION_TERMS | J135: Standard | K135: Interpretation | L135: Multiple | M135: Stable | N135: N | O135: Low | P135: None
A136: 3 | B136: COHERENCE_TERMS | C136: coherence | F136: Standard_English | G136: Y | I136: COHERENCE_TERMS | J136: Standard | K136: Interpretation | L136: Multiple | M136: Stable | N136: N | O136: Low | P136: Academic
A137: 3 | B137: COHERENCE_TERMS | C137: coherent | F137: Standard_English | G137: Y | I137: COHERENCE_TERMS | J137: Standard | K137: Interpretation | L137: Multiple | M137: Stable | N137: N | O137: Low | P137: Academic
A138: 3 | B138: COHERENCE_TERMS | C138: logos | F138: Standard_English | G138: Y | I138: COHERENCE_TERMS | J138: Standard | K138: Interpretation | L138: Multiple | M138: Stable | N138: N | O138: Low | P138: Academic
A139: 3 | B139: COHERENCE_TERMS | C139: quantum | F139: Standard_English | G139: Y | I139: COHERENCE_TERMS | J139: Standard | K139: Interpretation | L139: Multiple | M139: Stable | N139: N | O139: Low | P139: Academic
A140: 3 | B140: COHERENCE_TERMS | C140: decoherence | F140: Standard_English | G140: Y | I140: COHERENCE_TERMS | J140: Standard | K140: Interpretation | L140: Multiple | M140: Stable | N140: N | O140: Low | P140: Academic
A141: 3 | B141: COHERENCE_TERMS | C141: wavefunction | F141: Standard_English | G141: Y | I141: COHERENCE_TERMS | J141: Standard | K141: Interpretation | L141: Multiple | M141: Stable | N141: N | O141: Low | P141: Academic
A142: 2 | B142: COHERENCE_TERMS | C142: entropy | F142: Standard_English | G142: Y | I142: COHERENCE_TERMS | J142: Standard | K142: Interpretation | L142: Multiple | M142: Stable | N142: N | O142: Low | P142: Academic
A143: 2 | B143: COHERENCE_TERMS | C143: conservation | F143: Standard_English | G143: Y | I143: COHERENCE_TERMS | J143: Standard | K143: Interpretation | L143: Multiple | M143: Stable | N143: N | O143: Low | P143: Academic
A144: 2 | B144: COHERENCE_TERMS | C144: order | F144: Standard_English | G144: Y | I144: COHERENCE_TERMS | J144: Standard | K144: Interpretation | L144: Multiple | M144: Stable | N144: N | O144: Low | P144: Academic
A145: 2 | B145: COHERENCE_TERMS | C145: structure | F145: Standard_English | G145: Y | I145: COHERENCE_TERMS | J145: Standard | K145: Interpretation | L145: Multiple | M145: Stable | N145: N | O145: Low | P145: Academic
A146: 2 | B146: COHERENCE_TERMS | C146: framework | F146: Standard_English | G146: Y | I146: COHERENCE_TERMS | J146: Standard | K146: Interpretation | L146: Multiple | M146: Stable | N146: N | O146: Low | P146: Academic
A147: 2 | B147: COHERENCE_TERMS | C147: principle | F147: Standard_English | G147: Y | I147: COHERENCE_TERMS | J147: Standard | K147: Interpretation | L147: Multiple | M147: Stable | N147: N | O147: Low | P147: Academic
... A165: 2 | B165: COHERENCE_TERMS | C165: fundamental | F165: Standard_English | G165: Y | I165: COHERENCE_TERMS | J165: Standard | K165: Interpretation | L165: Multiple | M165: Stable | N165: N | O165: Low | P165: Academic
A166: gravity | B166: ME_VARS | C166: G_gravity_belonging | F166: Standard_English | G166: Y | I166: ME_VARS | J166: Standard | K166: Interpretation | L166: Multiple | M166: Stable | N166: N | O166: Low | P166: Academic
A167: belonging | B167: ME_VARS | C167: G_gravity_belonging | F167: Standard_English | G167: Y | I167: ME_VARS | J167: Standard | K167: Interpretation | L167: Multiple | M167: Stable | N167: N | O167: Low | P167: Academic
A168: community | B168: ME_VARS | C168: G_gravity_belonging | F168: Standard_English | G168: Y | I168: ME_VARS | J168: Standard | K168: Interpretation | L168: Multiple | M168: Stable | N168: N | O168: Low | P168: Academic
A169: gather | B169: ME_VARS | C169: G_gravity_belonging | F169: Standard_English | G169: Y | I169: ME_VARS | J169: Standard | K169: Interpretation | L169: Multiple | M169: Stable | N169: N | O169: Low | P169: Academic
A170: love | B170: ME_VARS | C170: G_gravity_belonging | F170: Standard_English | G170: Y | I170: ME_VARS | J170: Diluted_2025 | K170: Interpretation | L170: Multiple | M170: Stable | N170: N | O170: Low | P170: Pastoral
A171: binding | B171: ME_VARS | C171: G_gravity_belonging | F171: Standard_English | G171: Y | I171: ME_VARS | J171: Standard | K171: Interpretation | L171: Multiple | M171: Stable | N171: N | O171: Low | P171: Academic
...

Sheet AAVE-Ebonics
A1: I need you to fill in the blank columns for every row in the MASTER_TERM_REGISTRY sheet. Each row is a term in a semantic classification lexicon. The filled columns are: term, category, fruit_mapping, tier, weight, dialect, active, subcategory, source_sheets. The blank columns that need filling are:
A3: COLUMN F — semantic_register: Choose one of: Full_1828 / Standard / Diluted_2025 / Inverted
A4: {=- Full_1828 = the term carries its full historical/theological/moral depth} -> #NAME? | B4: Category | C4: Tier | D4: Subcategory | E4: Active | F4: Weight Note
A5: {=- Standard = Standard modern meaning, intact but no theological overtone} -> #NAME? | B5: Fruit | C5: Tier 1 | D5: direct_truth | E5: Y | F5: 2x weight (oath-level truth)
A6: - Diluted_2025 = meaning has been weakened or bleached in contemporary usage | B6: Fruit | C6: Tier 1 | D6: direct_truth | E6: Y | F6: 2x weight (oath-level truth)
A7: - Inverted = meaning has flipped or been co-opted to serve the opposite function | B7: Fruit | C7: Tier 1 | D7: direct_truth | E7: Y | F7: 2x weight (oath-level truth)
A8: - Default: if the term is in the AAVE dialect, default to Standard. If it's a theological term (love, grace, faith, patience, faithfulness), lean toward Diluted_2025 unless the subcategory is direct_truth or oath-level. | B8: Fruit | C8: Tier 1 | D8: direct_truth | E8: Y | F8: 2x weight (oath-level truth)
B9: Fruit | C9: Tier 1 | D9: direct_truth | E9: Y | F9: 2x weight (oath-level truth)
A10: COLUMN H — belief_deriv_level: Choose one of: Reality / Distinction / Signal / Perception / Interpretation / Meaning / Belief / Identity / Action / World | B10: Fruit | C10: Tier 1 | D10: direct_truth | E10: Y | F10: 2x weight (oath-level truth)
A11: {=- Reality = ground facts. Signal = data/evidence. Perception = how things appear. Interpretation = meaning-making. meaning = _xleta.VALUE-placed. Belief = held proposition. Identity = who I am. Action = behavior. World = institution-building.} -> #NAME? | B11: Fruit | C11: Tier 1 | D11: direct_truth | E11: Y | F11: 2x weight (oath-level truth)
A12: - Default: Grounding terms → Signal or Reality. Fruit terms → Meaning or Belief. Anti-Fruit terms → Perception or Interpretation. Propaganda terms → Meaning or Identity. Claim terms → Belief. Evidence terms → Signal. Hedge terms → Interpretation. | B12: Fruit | C12: Tier 1 | D12: direct_truth | E12: Y | F12: 2x weight (oath-level truth)
B13: Fruit | C13: Tier 1 | D13: direct_truth | E13: Y | F13: 2x weight (oath-level truth)
A14: COLUMN I — six_needs_served: Choose one of: Certainty / Variety / Significance / Connection / Growth / Contribution / Multiple / None | B14: Fruit | C14: Tier 1 | D14: direct_truth | E14: Y | F14: 2x weight (oath-level truth)
A15: - Certainty = safety, stability. Variety = change, stimulation. Significance = importance, recognition. Connection = bonds, belonging. Growth = learning, expansion. Contribution = giving, service. | B15: Fruit | C15: Tier 1 | D15: direct_truth | E15: Y | F15: 2x weight (oath-level truth)
A16: - Default: Most Fruit terms → Connection or Contribution. Most Anti-Fruit terms → Significance or Certainty. Grounding terms → Certainty. Propaganda terms → Significance. Bridge terms → None. | B16: Fruit | C16: Tier 1 | D16: direct_truth | E16: Y | F16: 2x weight (oath-level truth)
B17: Fruit | C17: Tier 1 | D17: direct_truth | E17: Y | F17: 2x weight (oath-level truth)
A18: COLUMN K — polarity_stability: Choose one of: Stable / Context-flip / Sarcasm-risk / Dialect-dependent | B18: Fruit | C18: Tier 1 | D18: direct_truth | E18: Y | F18: 2x weight (oath-level truth)
A19: {=- Stable = always the same polarity. Context-flip = Context can reverse meaning. Sarcasm-risk = frequently sarcastic. Dialect-dependent = meaning changes by community.} -> #NAME? | B19: Fruit | C19: Tier 1 | D19: direct_truth | E19: Y | F19: 2x weight (oath-level truth)
A20: - Default: Tier 1 terms → Stable. AAVE terms → check for dialect-dependency. Terms like "interesting," "fine," "sure," "nice" → Sarcasm-risk or Context-flip. | B20: Fruit | C20: Tier 1 | D20: direct_truth | E20: Y | F20: 2x weight (oath-level truth)
B21: Fruit | C21: Tier 1 | D21: direct_truth | E21: Y | F21: 2x weight (oath-level truth)
A22: COLUMN L — ai_detection: Y or N | B22: Fruit | C22: Tier 1 | D22: direct_truth | E22: Y | F22: 2x weight (oath-level truth)
A23: - Y = this term is characteristic of AI-generated text (e.g., delve, tapestry, nuanced, multifaceted, it's important to note, I'd be happy to, certainly, absolutely, in conclusion, comprehensive, robust, leverage, facilitate, utilize, albeit, furthermore, moreover, notable, noteworthy, underscores, underpin) | B23: Fruit | C23: Tier 1 | D23: direct_truth | E23: Y | F23: 2x weight (oath-level truth)
A24: - Default: N for most terms. Y only for known AI-speak markers. | B24: Fruit | C24: Tier 1 | D24: direct_truth | E24: Y | F24: 2x weight (oath-level truth)
B25: Fruit | C25: Tier 1 | D25: direct_truth | E25: Y | F25: 2x weight (oath-level truth)
A26: COLUMN M — danger_level: Choose one of: Low / Medium / High / Critical | B26: Fruit | C26: Tier 1 | D26: direct_truth | E26: Y | F26: 2x weight (oath-level truth)
A27: - Low = safe in most contexts. Medium = context-dependent. High = frequently overclaims. Critical = almost always overclaims or signals manipulation. | B27: Fruit | C27: Tier 1 | D27: direct_truth | E27: Y | F27: 2x weight (oath-level truth)
A28: - Default: Tier 1 Fruit → Low. Tier 4 peripheral → Low. Propaganda terms → High or Critical. Absolute terms (proves, always, never) → High. Hedge terms → Low. Claim-strength terms → Medium to High depending on subcategory. | B28: Fruit | C28: Tier 1 | D28: direct_truth | E28: Y | F28: 2x weight (oath-level truth)
B29: Fruit | C29: Tier 1 | D29: direct_truth | E29: Y | F29: 2x weight (oath-level truth)
A30: COLUMN N — shibboleth_cluster: Choose one of: Pastoral / Therapeutic / Academic / Legal / Medical / Military / Street / Tech / Trades / Finance / Political / AI / None | B30: Fruit | C30: Tier 1 | D30: direct_truth | E30: Y | F30: 2x weight (oath-level truth)
A31: - This is the profession/community fingerprint. Which community would immediately recognize this term as "one of theirs"? | B31: Fruit | C31: Tier 1 | D31: direct_truth | E31: Y | F31: 2x weight (oath-level truth)
A32: - Default: AAVE terms → Street. Terms from theophysics_scorer.py → Academic. Terms with theological subcategory → Pastoral. Terms like "boundaries," "hold space," "validate" → Therapeutic. Terms like "leverage," "utilize" → could be Tech, Finance, or AI. | B32: Fruit | C32: Tier 1 | D32: direct_truth | E32: Y | F32: 2x weight (oath-level truth)
B33: Fruit | C33: Tier 1 | D33: direct_truth | E33: Y | F33: 2x weight (oath-level truth)
A34: Work through every row. Where you're unsure, use the defaults above. Speed matters more than perfection here — this is a first pass that will be audited by a specialized classification model afterward. | B34: Fruit | C34: Tier 1 | D34: direct_truth | E34: Y | F34: 2x weight (oath-level truth)
A35: I swear | B35: Fruit | C35: Tier 1 | D35: direct_truth | E35: Y | F35: 2x weight (oath-level truth)
A36: keep it 100 | B36: Fruit | C36: Tier 1 | D36: direct_truth | E36: Y | F36: 2x weight (oath-level truth)
A37: keep it a buck | B37: Fruit | C37: Tier 1 | D37: direct_truth | E37: Y | F37: 2x weight (oath-level truth)
A38: keep it a stack | B38: Fruit | C38: Tier 1 | D38: direct_truth | E38: Y | F38: 2x weight (oath-level truth)
A39: keep it real | B39: Fruit | C39: Tier 1 | D39: direct_truth | E39: Y | F39: 2x weight (oath-level truth)
A40: keep it G | B40: Fruit | C40: Tier 1 | D40: direct_truth | E40: Y | F40: 2x weight (oath-level truth)
A41: periodt | B41: Fruit | C41: Tier 1 | D41: direct_truth | E41: Y | F41: 2x weight (oath-level truth)
...

Sheet MASTER_README
A1: Is it working Goodbye more when I go on there The last one I I don't know what I'm gonna do today | B1: role | C1: notes
A2: MASTER_README | B2: orientation | C2: Canonical single workbook. Subjective sheets are indexed separately below.
A3: Fruit Semantic Architecture | B3: general
A4: README | B4: general
A5: WISDOM_TERMS | B5: subjective
A6: KNOWLEDGE_TERMS | B6: subjective
A7: COHERENCE_TERMS | B7: subjective
A8: FRUITS | B8: subjective
A9: ME_VARS | B9: general
A10: CLAIM_TERMS | B10: subjective
A11: EVIDENCE_TERMS | B11: subjective
A12: FALSIFY_TERMS | B12: subjective
A13: DEPENDENCY_TERMS | B13: subjective
A14: HEDGE_TERMS | B14: subjective
... A24: DOC_TYPE_PATTERNS | B24: subjective

Sheet TEXT_GRADER
A1: TEXT GRADER — Import & Grade Sentence-by-Sentence
A2: Paste text into B10 (one block). Sentences auto-split below and are scored word-by-word against the chosen lexicon.
A4: CONFIG | E4: RESULTS
A5: Lexicon sheet | B5: SEMANTIC_BUCKETS | C5: <- name of the term table to grade against | E5: Sentences | F5: =COUNT(A14:A213) -> 0
A6: Lexicon range (term col) | B6: SEMANTIC_BUCKETS!$A$2:$A$348 | C6: <- terms (edit formulas in row 14 if you change the lexicon) | E6: Total score | F6: =SUM(E14:E213) -> 0
A7: Weight col | B7: SEMANTIC_BUCKETS!$E$2:$E$348 | C7: <- weights (must align row-for-row with terms) | E7: Avg score/sentence | F7: =IFERROR(F6/F5,0) -> 0
A8: Bucket col | B8: SEMANTIC_BUCKETS!$B$2:$B$348 | C8: <- buckets (must align row-for-row with terms) | E8: PASS / WARN / FAIL | F8: =COUNTIF(G14:G213,"PASS")&" / "&COUNTIF(G14:G213,"WARN")&" / "&COUNTIF(G14:G213,"FAIL") -> 0 / 0 / 0
A9: Warn threshold (score ≥) | B9: 3 | C9: <- sentence flagged WARN at/above this matched-weight | E9: Fail threshold (score ≥) | F9: 6
A10: PASTE TEXT HERE →
A12: GRADED SENTENCES
A13: # | B13: Sentence | C13: Words | D13: Matched terms | E13: Score | F13: Top bucket | G13: Grade | H13: Matched list
A14: =IF(B14="","",ROW()-13) | B14: {=IFERROR(_xlfn.LET(_xlpm.s,$B$10,_xlpm.norm,SUBSTITUTE(SUBSTITUTE(_xlpm.s,"!","."),"?","."),_xlpm.parts,_xlfn.TEXTSPLIT(_xlpm.norm,,".",TRUE),TRIM(INDEX(_xlpm.parts,ROW()-13))),"")} | C14: =IF(B14="","",IF(TRIM(B14)="",0,LEN(TRIM(B14))-LEN(SUBSTITUTE(TRIM(B14)," ",""))+1)) | D14: {=IF(B14="","",SUMPRODUCT(--ISNUMBER(SEARCH(" "&SEMANTIC_BUCKETS!$A$2:$A$348&" "," "&B14&" "))))} | E14: {=IF(B14="","",SUMPRODUCT(--ISNUMBER(SEARCH(" "&SEMANTIC_BUCKETS!$A$2:$A$348&" "," "&B14&" ")),SEMANTIC_BUCKETS!$E$2:$E$348))} | F14: {=IF(OR(B14="",D14=0),"",INDEX(SEMANTIC_BUCKETS!$B$2:$B$348,MATCH(TRUE,ISNUMBER(SEARCH(" "&SEMANTIC_BUCKETS!$A$2:$A$348&" "," "&B14&" ")),0)))} | G14: =IF(B14="","",IF(E14>=$F$9,"FAIL",IF(E14>=$B$9,"WARN","PASS"))) | H14: {=IF(OR(B14="",D14=0),"",_xlfn.TEXTJOIN(", ",TRUE,IF(ISNUMBER(SEARCH(" "&SEMANTIC_BUCKETS!$A$2:$A$348&" "," "&B14&" ")),SEMANTIC_BUCKETS!$A$2:$A$348,"")))}
A15: =IF(B15="","",ROW()-13) | B15: {=IFERROR(_xlfn.LET(_xlpm.s,$B$10,_xlpm.norm,SUBSTITUTE(SUBSTITUTE(_xlpm.s,"!","."),"?","."),_xlpm.parts,_xlfn.TEXTSPLIT(_xlpm.norm,,".",TRUE),TRIM(INDEX(_xlpm.parts,ROW()-13))),"")} | C15: =IF(B15="","",IF(TRIM(B15)="",0,LEN(TRIM(B15))-LEN(SUBSTITUTE(TRIM(B15)," ",""))+1)) | D15: {=IF(B15="","",SUMPRODUCT(--ISNUMBER(SEARCH(" "&SEMANTIC_BUCKETS!$A$2:$A$348&" "," "&B15&" "))))} | E15: {=IF(B15="","",SUMPRODUCT(--ISNUMBER(SEARCH(" "&SEMANTIC_BUCKETS!$A$2:$A$348&" "," "&B15&" ")),SEMANTIC_BUCKETS!$E$2:$E$348))} | F15: {=IF(OR(B15="",D15=0),"",INDEX(SEMANTIC_BUCKETS!$B$2:$B$348,MATCH(TRUE,ISNUMBER(SEARCH(" "&SEMANTIC_BUCKETS!$A$2:$A$348&" "," "&B15&" ")),0)))} | G15: =IF(B15="","",IF(E15>=$F$9,"FAIL",IF(E15>=$B$9,"WARN","PASS"))) | H15: {=IF(OR(B15="",D15=0),"",_xlfn.TEXTJOIN(", ",TRUE,IF(ISNUMBER(SEARCH(" "&SEMANTIC_BUCKETS!$A$2:$A$348&" "," "&B15&" ")),SEMANTIC_BUCKETS!$A$2:$A$348,"")))}
A16: =IF(B16="","",ROW()-13) | B16: {=IFERROR(_xlfn.LET(_xlpm.s,$B$10,_xlpm.norm,SUBSTITUTE(SUBSTITUTE(_xlpm.s,"!","."),"?","."),_xlpm.parts,_xlfn.TEXTSPLIT(_xlpm.norm,,".",TRUE),TRIM(INDEX(_xlpm.parts,ROW()-13))),"")} | C16: =IF(B16="","",IF(TRIM(B16)="",0,LEN(TRIM(B16))-LEN(SUBSTITUTE(TRIM(B16)," ",""))+1)) | D16: {=IF(B16="","",SUMPRODUCT(--ISNUMBER(SEARCH(" "&SEMANTIC_BUCKETS!$A$2:$A$348&" "," "&B16&" "))))} | E16: {=IF(B16="","",SUMPRODUCT(--ISNUMBER(SEARCH(" "&SEMANTIC_BUCKETS!$A$2:$A$348&" "," "&B16&" ")),SEMANTIC_BUCKETS!$E$2:$E$348))} | F16: {=IF(OR(B16="",D16=0),"",INDEX(SEMANTIC_BUCKETS!$B$2:$B$348,MATCH(TRUE,ISNUMBER(SEARCH(" "&SEMANTIC_BUCKETS!$A$2:$A$348&" "," "&B16&" ")),0)))} | G16: =IF(B16="","",IF(E16>=$F$9,"FAIL",IF(E16>=$B$9,"WARN","PASS"))) | H16: {=IF(OR(B16="",D16=0),"",_xlfn.TEXTJOIN(", ",TRUE,IF(ISNUMBER(SEARCH(" "&SEMANTIC_BUCKETS!$A$2:$A$348&" "," "&B16&" ")),SEMANTIC_BUCKETS!$A$2:$A$348,"")))}
A17: =IF(B17="","",ROW()-13) | B17: {=IFERROR(_xlfn.LET(_xlpm.s,$B$10,_xlpm.norm,SUBSTITUTE(SUBSTITUTE(_xlpm.s,"!","."),"?","."),_xlpm.parts,_xlfn.TEXTSPLIT(_xlpm.norm,,".",TRUE),TRIM(INDEX(_xlpm.parts,ROW()-13))),"")} | C17: =IF(B17="","",IF(TRIM(B17)="",0,LEN(TRIM(B17))-LEN(SUBSTITUTE(TRIM(B17)," ",""))+1)) | D17: {=IF(B17="","",SUMPRODUCT(--ISNUMBER(SEARCH(" "&SEMANTIC_BUCKETS!$A$2:$A$348&" "," "&B17&" "))))} | E17: {=IF(B17="","",SUMPRODUCT(--ISNUMBER(SEARCH(" "&SEMANTIC_BUCKETS!$A$2:$A$348&" "," "&B17&" ")),SEMANTIC_BUCKETS!$E$2:$E$348))} | F17: {=IF(OR(B17="",D17=0),"",INDEX(SEMANTIC_BUCKETS!$B$2:$B$348,MATCH(TRUE,ISNUMBER(SEARCH(" "&SEMANTIC_BUCKETS!$A$2:$A$348&" "," "&B17&" ")),0)))} | G17: =IF(B17="","",IF(E17>=$F$9,"FAIL",IF(E17>=$B$9,"WARN","PASS"))) | H17: {=IF(OR(B17="",D17=0),"",_xlfn.TEXTJOIN(", ",TRUE,IF(ISNUMBER(SEARCH(" "&SEMANTIC_BUCKETS!$A$2:$A$348&" "," "&B17&" ")),SEMANTIC_BUCKETS!$A$2:$A$348,"")))}
A18: =IF(B18="","",ROW()-13) | B18: {=IFERROR(_xlfn.LET(_xlpm.s,$B$10,_xlpm.norm,SUBSTITUTE(SUBSTITUTE(_xlpm.s,"!","."),"?","."),_xlpm.parts,_xlfn.TEXTSPLIT(_xlpm.norm,,".",TRUE),TRIM(INDEX(_xlpm.parts,ROW()-13))),"")} | C18: =IF(B18="","",IF(TRIM(B18)="",0,LEN(TRIM(B18))-LEN(SUBSTITUTE(TRIM(B18)," ",""))+1)) | D18: {=IF(B18="","",SUMPRODUCT(--ISNUMBER(SEARCH(" "&SEMANTIC_BUCKETS!$A$2:$A$348&" "," "&B18&" "))))} | E18: {=IF(B18="","",SUMPRODUCT(--ISNUMBER(SEARCH(" "&SEMANTIC_BUCKETS!$A$2:$A$348&" "," "&B18&" ")),SEMANTIC_BUCKETS!$E$2:$E$348))} | F18: {=IF(OR(B18="",D18=0),"",INDEX(SEMANTIC_BUCKETS!$B$2:$B$348,MATCH(TRUE,ISNUMBER(SEARCH(" "&SEMANTIC_BUCKETS!$A$2:$A$348&" "," "&B18&" ")),0)))} | G18: =IF(B18="","",IF(E18>=$F$9,"FAIL",IF(E18>=$B$9,"WARN","PASS"))) | H18: {=IF(OR(B18="",D18=0),"",_xlfn.TEXTJOIN(", ",TRUE,IF(ISNUMBER(SEARCH(" "&SEMANTIC_BUCKETS!$A$2:$A$348&" "," "&B18&" ")),SEMANTIC_BUCKETS!$A$2:$A$348,"")))}
A19: =IF(B19="","",ROW()-13) | B19: {=IFERROR(_xlfn.LET(_xlpm.s,$B$10,_xlpm.norm,SUBSTITUTE(SUBSTITUTE(_xlpm.s,"!","."),"?","."),_xlpm.parts,_xlfn.TEXTSPLIT(_xlpm.norm,,".",TRUE),TRIM(INDEX(_xlpm.parts,ROW()-13))),"")} | C19: =IF(B19="","",IF(TRIM(B19)="",0,LEN(TRIM(B19))-LEN(SUBSTITUTE(TRIM(B19)," ",""))+1)) | D19: {=IF(B19="","",SUMPRODUCT(--ISNUMBER(SEARCH(" "&SEMANTIC_BUCKETS!$A$2:$A$348&" "," "&B19&" "))))} | E19: {=IF(B19="","",SUMPRODUCT(--ISNUMBER(SEARCH(" "&SEMANTIC_BUCKETS!$A$2:$A$348&" "," "&B19&" ")),SEMANTIC_BUCKETS!$E$2:$E$348))} | F19: {=IF(OR(B19="",D19=0),"",INDEX(SEMANTIC_BUCKETS!$B$2:$B$348,MATCH(TRUE,ISNUMBER(SEARCH(" "&SEMANTIC_BUCKETS!$A$2:$A$348&" "," "&B19&" ")),0)))} | G19: =IF(B19="","",IF(E19>=$F$9,"FAIL",IF(E19>=$B$9,"WARN","PASS"))) | H19: {=IF(OR(B19="",D19=0),"",_xlfn.TEXTJOIN(", ",TRUE,IF(ISNUMBER(SEARCH(" "&SEMANTIC_BUCKETS!$A$2:$A$348&" "," "&B19&" ")),SEMANTIC_BUCKETS!$A$2:$A$348,"")))}
A20: =IF(B20="","",ROW()-13) | B20: {=IFERROR(_xlfn.LET(_xlpm.s,$B$10,_xlpm.norm,SUBSTITUTE(SUBSTITUTE(_xlpm.s,"!","."),"?","."),_xlpm.parts,_xlfn.TEXTSPLIT(_xlpm.norm,,".",TRUE),TRIM(INDEX(_xlpm.parts,ROW()-13))),"")} | C20: =IF(B20="","",IF(TRIM(B20)="",0,LEN(TRIM(B20))-LEN(SUBSTITUTE(TRIM(B20)," ",""))+1)) | D20: {=IF(B20="","",SUMPRODUCT(--ISNUMBER(SEARCH(" "&SEMANTIC_BUCKETS!$A$2:$A$348&" "," "&B20&" "))))} | E20: {=IF(B20="","",SUMPRODUCT(--ISNUMBER(SEARCH(" "&SEMANTIC_BUCKETS!$A$2:$A$348&" "," "&B20&" ")),SEMANTIC_BUCKETS!$E$2:$E$348))} | F20: {=IF(OR(B20="",D20=0),"",INDEX(SEMANTIC_BUCKETS!$B$2:$B$348,MATCH(TRUE,ISNUMBER(SEARCH(" "&SEMANTIC_BUCKETS!$A$2:$A$348&" "," "&B20&" ")),0)))} | G20: =IF(B20="","",IF(E20>=$F$9,"FAIL",IF(E20>=$B$9,"WARN","PASS"))) | H20: {=IF(OR(B20="",D20=0),"",_xlfn.TEXTJOIN(", ",TRUE,IF(ISNUMBER(SEARCH(" "&SEMANTIC_BUCKETS!$A$2:$A$348&" "," "&B20&" ")),SEMANTIC_BUCKETS!$A$2:$A$348,"")))}
A21: =IF(B21="","",ROW()-13) | B21: {=IFERROR(_xlfn.LET(_xlpm.s,$B$10,_xlpm.norm,SUBSTITUTE(SUBSTITUTE(_xlpm.s,"!","."),"?","."),_xlpm.parts,_xlfn.TEXTSPLIT(_xlpm.norm,,".",TRUE),TRIM(INDEX(_xlpm.parts,ROW()-13))),"")} | C21: =IF(B21="","",IF(TRIM(B21)="",0,LEN(TRIM(B21))-LEN(SUBSTITUTE(TRIM(B21)," ",""))+1)) | D21: {=IF(B21="","",SUMPRODUCT(--ISNUMBER(SEARCH(" "&SEMANTIC_BUCKETS!$A$2:$A$348&" "," "&B21&" "))))} | E21: {=IF(B21="","",SUMPRODUCT(--ISNUMBER(SEARCH(" "&SEMANTIC_BUCKETS!$A$2:$A$348&" "," "&B21&" ")),SEMANTIC_BUCKETS!$E$2:$E$348))} | F21: {=IF(OR(B21="",D21=0),"",INDEX(SEMANTIC_BUCKETS!$B$2:$B$348,MATCH(TRUE,ISNUMBER(SEARCH(" "&SEMANTIC_BUCKETS!$A$2:$A$348&" "," "&B21&" ")),0)))} | G21: =IF(B21="","",IF(E21>=$F$9,"FAIL",IF(E21>=$B$9,"WARN","PASS"))) | H21: {=IF(OR(B21="",D21=0),"",_xlfn.TEXTJOIN(", ",TRUE,IF(ISNUMBER(SEARCH(" "&SEMANTIC_BUCKETS!$A$2:$A$348&" "," "&B21&" ")),SEMANTIC_BUCKETS!$A$2:$A$348,"")))}
A22: =IF(B22="","",ROW()-13) | B22: {=IFERROR(_xlfn.LET(_xlpm.s,$B$10,_xlpm.norm,SUBSTITUTE(SUBSTITUTE(_xlpm.s,"!","."),"?","."),_xlpm.parts,_xlfn.TEXTSPLIT(_xlpm.norm,,".",TRUE),TRIM(INDEX(_xlpm.parts,ROW()-13))),"")} | C22: =IF(B22="","",IF(TRIM(B22)="",0,LEN(TRIM(B22))-LEN(SUBSTITUTE(TRIM(B22)," ",""))+1)) | D22: {=IF(B22="","",SUMPRODUCT(--ISNUMBER(SEARCH(" "&SEMANTIC_BUCKETS!$A$2:$A$348&" "," "&B22&" "))))} | E22: {=IF(B22="","",SUMPRODUCT(--ISNUMBER(SEARCH(" "&SEMANTIC_BUCKETS!$A$2:$A$348&" "," "&B22&" ")),SEMANTIC_BUCKETS!$E$2:$E$348))} | F22: {=IF(OR(B22="",D22=0),"",INDEX(SEMANTIC_BUCKETS!$B$2:$B$348,MATCH(TRUE,ISNUMBER(SEARCH(" "&SEMANTIC_BUCKETS!$A$2:$A$348&" "," "&B22&" ")),0)))} | G22: =IF(B22="","",IF(E22>=$F$9,"FAIL",IF(E22>=$B$9,"WARN","PASS"))) | H22: {=IF(OR(B22="",D22=0),"",_xlfn.TEXTJOIN(", ",TRUE,IF(ISNUMBER(SEARCH(" "&SEMANTIC_BUCKETS!$A$2:$A$348&" "," "&B22&" ")),SEMANTIC_BUCKETS!$A$2:$A$348,"")))}
A23: =IF(B23="","",ROW()-13) | B23: {=IFERROR(_xlfn.LET(_xlpm.s,$B$10,_xlpm.norm,SUBSTITUTE(SUBSTITUTE(_xlpm.s,"!","."),"?","."),_xlpm.parts,_xlfn.TEXTSPLIT(_xlpm.norm,,".",TRUE),TRIM(INDEX(_xlpm.parts,ROW()-13))),"")} | C23: =IF(B23="","",IF(TRIM(B23)="",0,LEN(TRIM(B23))-LEN(SUBSTITUTE(TRIM(B23)," ",""))+1)) | D23: {=IF(B23="","",SUMPRODUCT(--ISNUMBER(SEARCH(" "&SEMANTIC_BUCKETS!$A$2:$A$348&" "," "&B23&" "))))} | E23: {=IF(B23="","",SUMPRODUCT(--ISNUMBER(SEARCH(" "&SEMANTIC_BUCKETS!$A$2:$A$348&" "," "&B23&" ")),SEMANTIC_BUCKETS!$E$2:$E$348))} | F23: {=IF(OR(B23="",D23=0),"",INDEX(SEMANTIC_BUCKETS!$B$2:$B$348,MATCH(TRUE,ISNUMBER(SEARCH(" "&SEMANTIC_BUCKETS!$A$2:$A$348&" "," "&B23&" ")),0)))} | G23: =IF(B23="","",IF(E23>=$F$9,"FAIL",IF(E23>=$B$9,"WARN","PASS"))) | H23: {=IF(OR(B23="",D23=0),"",_xlfn.TEXTJOIN(", ",TRUE,IF(ISNUMBER(SEARCH(" "&SEMANTIC_BUCKETS!$A$2:$A$348&" "," "&B23&" ")),SEMANTIC_BUCKETS!$A$2:$A$348,"")))}
A24: =IF(B24="","",ROW()-13) | B24: {=IFERROR(_xlfn.LET(_xlpm.s,$B$10,_xlpm.norm,SUBSTITUTE(SUBSTITUTE(_xlpm.s,"!","."),"?","."),_xlpm.parts,_xlfn.TEXTSPLIT(_xlpm.norm,,".",TRUE),TRIM(INDEX(_xlpm.parts,ROW()-13))),"")} | C24: =IF(B24="","",IF(TRIM(B24)="",0,LEN(TRIM(B24))-LEN(SUBSTITUTE(TRIM(B24)," ",""))+1)) | D24: {=IF(B24="","",SUMPRODUCT(--ISNUMBER(SEARCH(" "&SEMANTIC_BUCKETS!$A$2:$A$348&" "," "&B24&" "))))} | E24: {=IF(B24="","",SUMPRODUCT(--ISNUMBER(SEARCH(" "&SEMANTIC_BUCKETS!$A$2:$A$348&" "," "&B24&" ")),SEMANTIC_BUCKETS!$E$2:$E$348))} | F24: {=IF(OR(B24="",D24=0),"",INDEX(SEMANTIC_BUCKETS!$B$2:$B$348,MATCH(TRUE,ISNUMBER(SEARCH(" "&SEMANTIC_BUCKETS!$A$2:$A$348&" "," "&B24&" ")),0)))} | G24: =IF(B24="","",IF(E24>=$F$9,"FAIL",IF(E24>=$B$9,"WARN","PASS"))) | H24: {=IF(OR(B24="",D24=0),"",_xlfn.TEXTJOIN(", ",TRUE,IF(ISNUMBER(SEARCH(" "&SEMANTIC_BUCKETS!$A$2:$A$348&" "," "&B24&" ")),SEMANTIC_BUCKETS!$A$2:$A$348,"")))}
A25: =IF(B25="","",ROW()-13) | B25: {=IFERROR(_xlfn.LET(_xlpm.s,$B$10,_xlpm.norm,SUBSTITUTE(SUBSTITUTE(_xlpm.s,"!","."),"?","."),_xlpm.parts,_xlfn.TEXTSPLIT(_xlpm.norm,,".",TRUE),TRIM(INDEX(_xlpm.parts,ROW()-13))),"")} | C25: =IF(B25="","",IF(TRIM(B25)="",0,LEN(TRIM(B25))-LEN(SUBSTITUTE(TRIM(B25)," ",""))+1)) | D25: {=IF(B25="","",SUMPRODUCT(--ISNUMBER(SEARCH(" "&SEMANTIC_BUCKETS!$A$2:$A$348&" "," "&B25&" "))))} | E25: {=IF(B25="","",SUMPRODUCT(--ISNUMBER(SEARCH(" "&SEMANTIC_BUCKETS!$A$2:$A$348&" "," "&B25&" ")),SEMANTIC_BUCKETS!$E$2:$E$348))} | F25: {=IF(OR(B25="",D25=0),"",INDEX(SEMANTIC_BUCKETS!$B$2:$B$348,MATCH(TRUE,ISNUMBER(SEARCH(" "&SEMANTIC_BUCKETS!$A$2:$A$348&" "," "&B25&" ")),0)))} | G25: =IF(B25="","",IF(E25>=$F$9,"FAIL",IF(E25>=$B$9,"WARN","PASS"))) | H25: {=IF(OR(B25="",D25=0),"",_xlfn.TEXTJOIN(", ",TRUE,IF(ISNUMBER(SEARCH(" "&SEMANTIC_BUCKETS!$A$2:$A$348&" "," "&B25&" ")),SEMANTIC_BUCKETS!$A$2:$A$348,"")))}
... A213: =IF(B213="","",ROW()-13) | B213: {=IFERROR(_xlfn.LET(_xlpm.s,$B$10,_xlpm.norm,SUBSTITUTE(SUBSTITUTE(_xlpm.s,"!","."),"?","."),_xlpm.parts,_xlfn.TEXTSPLIT(_xlpm.norm,,".",TRUE),TRIM(INDEX(_xlpm.parts,ROW()-13))),"")} | C213: =IF(B213="","",IF(TRIM(B213)="",0,LEN(TRIM(B213))-LEN(SUBSTITUTE(TRIM(B213)," ",""))+1)) | D213: {=IF(B213="","",SUMPRODUCT(--ISNUMBER(SEARCH(" "&SEMANTIC_BUCKETS!$A$2:$A$348&" "," "&B213&" "))))} | E213: {=IF(B213="","",SUMPRODUCT(--ISNUMBER(SEARCH(" "&SEMANTIC_BUCKETS!$A$2:$A$348&" "," "&B213&" ")),SEMANTIC_BUCKETS!$E$2:$E$348))} | F213: {=IF(OR(B213="",D213=0),"",INDEX(SEMANTIC_BUCKETS!$B$2:$B$348,MATCH(TRUE,ISNUMBER(SEARCH(" "&SEMANTIC_BUCKETS!$A$2:$A$348&" "," "&B213&" ")),0)))} | G213: =IF(B213="","",IF(E213>=$F$9,"FAIL",IF(E213>=$B$9,"WARN","PASS"))) | H213: {=IF(OR(B213="",D213=0),"",_xlfn.TEXTJOIN(", ",TRUE,IF(ISNUMBER(SEARCH(" "&SEMANTIC_BUCKETS!$A$2:$A$348&" "," "&B213&" ")),SEMANTIC_BUCKETS!$A$2:$A$348,"")))}
A215: BUCKET BREAKDOWN
A216: Bucket | B216: Sentences hit
A217: ANTI_FRUIT_BEHAVIOR_EXPANSION | B217: =COUNTIF($F$14:$F$213,A217) -> 0
A218: CLAIM_STRENGTH | B218: =COUNTIF($F$14:$F$213,A218) -> 0
A219: DANGER_LANGUAGE | B219: =COUNTIF($F$14:$F$213,A219) -> 0
A220: DRIFT_WARNING | B220: =COUNTIF($F$14:$F$213,A220) -> 0
A221: EVIDENCE_MATURITY | B221: =COUNTIF($F$14:$F$213,A221) -> 0
A222: FALSIFICATION | B222: =COUNTIF($F$14:$F$213,A222) -> 0
A223: FORMAL_PROOF | B223: =COUNTIF($F$14:$F$213,A223) -> 0
A224: FRUIT_BEHAVIOR_EXPANSION | B224: =COUNTIF($F$14:$F$213,A224) -> 0
A225: METHODS_PROVENANCE | B225: =COUNTIF($F$14:$F$213,A225) -> 0
A226: PREFERRED_REPLACEMENT | B226: =COUNTIF($F$14:$F$213,A226) -> 0
A227: REDUCTION_QUALITY | B227: =COUNTIF($F$14:$F$213,A227) -> 0
A228: RELATION_TYPE | B228: =COUNTIF($F$14:$F$213,A228) -> 0
... A230: THEOLOGICAL_STATUS | B230: =COUNTIF($F$14:$F$213,A230) -> 0

Sheet SUPRA_INFRAQUE
A1: SUPRA INFRAQUE — Radical Epistemic Storage Schema v1
A2: Ontology-first, question-driven epistemic graph for the full Theophysics corpus — without collapsing theology into physics, treating mathematics as empirical proof, or hiding assumptions inside classifications.
A4: THE REDESIGN IN ONE SENTENCE
A5: The file is no longer the unit of knowledge: the system stores independently identifiable questions, statements, axioms, constitutive disclosures, definitions, derivations, bridges, evidence units, countermodels, predictions, protocols, tests, results, and interpretations — while files remain immutable provenance containers that may hold any number of those objects.
A7: GOVERNING COMMITMENTS
A8: 2.1 Ontology before classification | B8: First ask what kind of thing a record is and what it asserts. Do not begin by forcing it into a scientific, theological, mathematical, or philosophical verdict.
A9: 2.2 Questions before inferred answers | B9: Neutral questions define the information slots. A question may specify a contrast, test, or required distinction; it may not presuppose the preferred conclusion.
A10: 2.3 Classification is multidimensional | B10: No single label represents both what a statement does and what it is about. Logical role and ontological domain are independent axes, plus warrant, status, relation to A0, mode, testability.
A11: 2.4 Unpacking is not addition | B11: A0 is one content-rich Triune axiom. Trinity, Being, Truth, Goodness, Love, relational distinction, positive fruits are constitutive disclosures/semantic unpackings — not independent axioms unless an argument explicitly posits another primitive.
A12: 2.5 A bridge is a claim | B12: No cross-domain transition is automatic. Each must be stored as a bridge dossier with mapping, preserved structure, assumptions, loss, direction, and tests.
A13: 2.6 Evidence is not interpretation | B13: Observations, measurements, quotations, datasets, and formal results are stored separately from what an author believes they mean. Competing interpretations may cite the same evidence unit.
A14: 2.7 Good and privation are not forced into symmetry | B14: The schema can represent truth as prior to falsehood, life to death, good to corruption. Negative states may be privative/parasitic/corruptive/derivative rather than co-original positive substances. A representational capability, not a DB-imposed conclusion.
A15: 2.8 Append, assess, supersede — do not silently overwrite | B15: Historical classifications and assessments remain visible. Corrections create new versions or superseding records so the development of the theory can be audited.
A17: THE SIX INTERLOCKING PLANES | B17: Stores | C17: Governing question
A18: Provenance | B18: artifacts, versions, spans, authors, dates, hashes | C18: Where exactly did this come from?
A19: Inquiry | B19: neutral questions, runs, responses, leakage checks | C19: What was asked, under what framing, and what appeared?
A20: Semantic | B20: statements and other epistemic objects | C20: What exactly is being said or represented?
A21: Inferential | B21: typed relationships and warrants | C21: How does one object depend on or affect another?
A22: Evaluation | B22: evidence, formalization, bridges, tests, objections | C22: What licenses, limits, tests, or defeats it?
A23: Governance | B23: versions, statuses, conflicts, decisions, audit trail | C23: Who changed what, why, and with what authority?
A24: Logical planes, not necessarily separate databases. PostgreSQL = authoritative store; a graph projection supports traversal; vector indexes assist retrieval but must never become the source of truth.
A26: THREE INQUIRY LEVELS — Methodus Veritatis Supra Infraque
A27: Supra-systemic | B27: Asks what must be true for the system, distinction, inquiry, or meaning to be possible.
A28: Intra-systemic | B28: Asks what the proposed system claims and how its parts relate.
A29: Infra-systemic | B29: Asks what observable, formal, experiential, or behavioral consequences occur within implementations.

Sheet FRUIT_RETRIEVAL_LEXICON_V2
A1: FRUIT RETRIEVAL LEXICON V2 — retrieval hierarchy with semantic controls
A2: Retrieval class | B2: Meaning / scanner handling
A3: CANONICAL | B3: Exact named fruit — high-confidence hit
A4: DIRECT | B4: Near-synonym or grammatical form — high-confidence hit
A5: FUNCTIONAL | B5: Describes the fruit in action — medium-confidence; inspect context
A6: RELATIONAL | B6: Often co-occurs but can mean something else — low-confidence; context required
A7: AMBIGUOUS | B7: May indicate several fruits or none — do not assign automatically
A8: ANTI | B8: Counter-orientation or corruption — separate negative signal
A9: GOVERNING | B9: Truth terms — track globally; do not score as a ninth fruit
A11: fruit_key | B11: fruit_display | C11: greek_term | D11: term | E11: normalized_term | F11: retrieval_class | G11: core_semantic_center | H11: boundary_note
A12: love | B12: Love | C12: agapē | D12: love | E12: love | F12: CANONICAL | G12: Willing, seeking, protecting, and participating in another's true good without reducing them to use, exchange, tribe, sentiment, or possession. | H12: Love is not identical to approval, permissiveness, emotional intensity, sexual desire, tribal loyalty, or nonjudgment. It must remain ordered to true good.
A13: love | B13: Love | C13: agapē | D13: agape | E13: agape | F13: CANONICAL | G13: Willing, seeking, protecting, and participating in another's true good without reducing them to use, exchange, tribe, sentiment, or possession. | H13: Love is not identical to approval, permissiveness, emotional intensity, sexual desire, tribal loyalty, or nonjudgment. It must remain ordered to true good.
A14: love | B14: Love | C14: agapē | D14: charity | E14: charity | F14: CANONICAL | G14: Willing, seeking, protecting, and participating in another's true good without reducing them to use, exchange, tribe, sentiment, or possession. | H14: Love is not identical to approval, permissiveness, emotional intensity, sexual desire, tribal loyalty, or nonjudgment. It must remain ordered to true good.
A15: love | B15: Love | C15: agapē | D15: affection | E15: affection | F15: DIRECT | G15: Willing, seeking, protecting, and participating in another's true good without reducing them to use, exchange, tribe, sentiment, or possession. | H15: Love is not identical to approval, permissiveness, emotional intensity, sexual desire, tribal loyalty, or nonjudgment. It must remain ordered to true good.
A16: love | B16: Love | C16: agapē | D16: benevolence | E16: benevolence | F16: DIRECT | G16: Willing, seeking, protecting, and participating in another's true good without reducing them to use, exchange, tribe, sentiment, or possession. | H16: Love is not identical to approval, permissiveness, emotional intensity, sexual desire, tribal loyalty, or nonjudgment. It must remain ordered to true good.
A17: love | B17: Love | C17: agapē | D17: compassion | E17: compassion | F17: DIRECT | G17: Willing, seeking, protecting, and participating in another's true good without reducing them to use, exchange, tribe, sentiment, or possession. | H17: Love is not identical to approval, permissiveness, emotional intensity, sexual desire, tribal loyalty, or nonjudgment. It must remain ordered to true good.
A18: love | B18: Love | C18: agapē | D18: mercy | E18: mercy | F18: DIRECT | G18: Willing, seeking, protecting, and participating in another's true good without reducing them to use, exchange, tribe, sentiment, or possession. | H18: Love is not identical to approval, permissiveness, emotional intensity, sexual desire, tribal loyalty, or nonjudgment. It must remain ordered to true good.
A19: love | B19: Love | C19: agapē | D19: care | E19: care | F19: DIRECT | G19: Willing, seeking, protecting, and participating in another's true good without reducing them to use, exchange, tribe, sentiment, or possession. | H19: Love is not identical to approval, permissiveness, emotional intensity, sexual desire, tribal loyalty, or nonjudgment. It must remain ordered to true good.
A20: love | B20: Love | C20: agapē | D20: devotion | E20: devotion | F20: DIRECT | G20: Willing, seeking, protecting, and participating in another's true good without reducing them to use, exchange, tribe, sentiment, or possession. | H20: Love is not identical to approval, permissiveness, emotional intensity, sexual desire, tribal loyalty, or nonjudgment. It must remain ordered to true good.
A21: love | B21: Love | C21: agapē | D21: goodwill | E21: goodwill | F21: DIRECT | G21: Willing, seeking, protecting, and participating in another's true good without reducing them to use, exchange, tribe, sentiment, or possession. | H21: Love is not identical to approval, permissiveness, emotional intensity, sexual desire, tribal loyalty, or nonjudgment. It must remain ordered to true good.
A22: love | B22: Love | C22: agapē | D22: loving-kindness | E22: loving-kindness | F22: DIRECT | G22: Willing, seeking, protecting, and participating in another's true good without reducing them to use, exchange, tribe, sentiment, or possession. | H22: Love is not identical to approval, permissiveness, emotional intensity, sexual desire, tribal loyalty, or nonjudgment. It must remain ordered to true good.
... A546: truth | B546: Truth (governing) | C546: alētheia | D546: truth | E546: truth | F546: CANONICAL | G546: Governing condition: names and applies what is real. Truth governs the recognition and application of the nine fruits; it is not itself a ninth fruit. | H546: Truth is necessary but not sufficient. A statement can be factually accurate and still be delivered cruelly, manipulatively, prematurely, or dominantly. An act styled as 'loving' that conceals or distorts reality fails the governing condition.
A547: truth | B547: Truth (governing) | C547: alētheia | D547: TRUE | E547: TRUE | F547: CANONICAL | G547: Governing condition: names and applies what is real. Truth governs the recognition and application of the nine fruits; it is not itself a ninth fruit. | H547: Truth is necessary but not sufficient. A statement can be factually accurate and still be delivered cruelly, manipulatively, prematurely, or dominantly. An act styled as 'loving' that conceals or distorts reality fails the governing condition.
A548: truth | B548: Truth (governing) | C548: alētheia | D548: truthfulness | E548: truthfulness | F548: CANONICAL | G548: Governing condition: names and applies what is real. Truth governs the recognition and application of the nine fruits; it is not itself a ninth fruit. | H548: Truth is necessary but not sufficient. A statement can be factually accurate and still be delivered cruelly, manipulatively, prematurely, or dominantly. An act styled as 'loving' that conceals or distorts reality fails the governing condition.
A549: truth | B549: Truth (governing) | C549: alētheia | D549: honesty | E549: honesty | F549: DIRECT | G549: Governing condition: names and applies what is real. Truth governs the recognition and application of the nine fruits; it is not itself a ninth fruit. | H549: Truth is necessary but not sufficient. A statement can be factually accurate and still be delivered cruelly, manipulatively, prematurely, or dominantly. An act styled as 'loving' that conceals or distorts reality fails the governing condition.
A550: truth | B550: Truth (governing) | C550: alētheia | D550: candor | E550: candor | F550: DIRECT | G550: Governing condition: names and applies what is real. Truth governs the recognition and application of the nine fruits; it is not itself a ninth fruit. | H550: Truth is necessary but not sufficient. A statement can be factually accurate and still be delivered cruelly, manipulatively, prematurely, or dominantly. An act styled as 'loving' that conceals or distorts reality fails the governing condition.
A551: truth | B551: Truth (governing) | C551: alētheia | D551: sincerity | E551: sincerity | F551: DIRECT | G551: Governing condition: names and applies what is real. Truth governs the recognition and application of the nine fruits; it is not itself a ninth fruit. | H551: Truth is necessary but not sufficient. A statement can be factually accurate and still be delivered cruelly, manipulatively, prematurely, or dominantly. An act styled as 'loving' that conceals or distorts reality fails the governing condition.
A552: truth | B552: Truth (governing) | C552: alētheia | D552: accuracy | E552: accuracy | F552: DIRECT | G552: Governing condition: names and applies what is real. Truth governs the recognition and application of the nine fruits; it is not itself a ninth fruit. | H552: Truth is necessary but not sufficient. A statement can be factually accurate and still be delivered cruelly, manipulatively, prematurely, or dominantly. An act styled as 'loving' that conceals or distorts reality fails the governing condition.
A553: truth | B553: Truth (governing) | C553: alētheia | D553: veracity | E553: veracity | F553: DIRECT | G553: Governing condition: names and applies what is real. Truth governs the recognition and application of the nine fruits; it is not itself a ninth fruit. | H553: Truth is necessary but not sufficient. A statement can be factually accurate and still be delivered cruelly, manipulatively, prematurely, or dominantly. An act styled as 'loving' that conceals or distorts reality fails the governing condition.
A554: truth | B554: Truth (governing) | C554: alētheia | D554: integrity | E554: integrity | F554: DIRECT | G554: Governing condition: names and applies what is real. Truth governs the recognition and application of the nine fruits; it is not itself a ninth fruit. | H554: Truth is necessary but not sufficient. A statement can be factually accurate and still be delivered cruelly, manipulatively, prematurely, or dominantly. An act styled as 'loving' that conceals or distorts reality fails the governing condition.
A555: truth | B555: Truth (governing) | C555: alētheia | D555: transparency | E555: transparency | F555: DIRECT | G555: Governing condition: names and applies what is real. Truth governs the recognition and application of the nine fruits; it is not itself a ninth fruit. | H555: Truth is necessary but not sufficient. A statement can be factually accurate and still be delivered cruelly, manipulatively, prematurely, or dominantly. An act styled as 'loving' that conceals or distorts reality fails the governing condition.
A556: truth | B556: Truth (governing) | C556: alētheia | D556: fidelity to reality | E556: fidelity to reality | F556: DIRECT | G556: Governing condition: names and applies what is real. Truth governs the recognition and application of the nine fruits; it is not itself a ninth fruit. | H556: Truth is necessary but not sufficient. A statement can be factually accurate and still be delivered cruelly, manipulatively, prematurely, or dominantly. An act styled as 'loving' that conceals or distorts reality fails the governing condition.
A557: truth | B557: Truth (governing) | C557: alētheia | D557: factuality | E557: factuality | F557: DIRECT | G557: Governing condition: names and applies what is real. Truth governs the recognition and application of the nine fruits; it is not itself a ninth fruit. | H557: Truth is necessary but not sufficient. A statement can be factually accurate and still be delivered cruelly, manipulatively, prematurely, or dominantly. An act styled as 'loving' that conceals or distorts reality fails the governing condition.
A558: truth | B558: Truth (governing) | C558: alētheia | D558: correctness | E558: correctness | F558: DIRECT | G558: Governing condition: names and applies what is real. Truth governs the recognition and application of the nine fruits; it is not itself a ninth fruit. | H558: Truth is necessary but not sufficient. A statement can be factually accurate and still be delivered cruelly, manipulatively, prematurely, or dominantly. An act styled as 'loving' that conceals or distorts reality fails the governing condition.
A559: truth | B559: Truth (governing) | C559: alētheia | D559: names what is real | E559: names what is real | F559: FUNCTIONAL | G559: Governing condition: names and applies what is real. Truth governs the recognition and application of the nine fruits; it is not itself a ninth fruit. | H559: Truth is necessary but not sufficient. A statement can be factually accurate and still be delivered cruelly, manipulatively, prematurely, or dominantly. An act styled as 'loving' that conceals or distorts reality fails the governing condition.
... A595: truth | B595: Truth (governing) | C595: alētheia | D595: gaslighting | E595: gaslighting | F595: ANTI | G595: Governing condition: names and applies what is real. Truth governs the recognition and application of the nine fruits; it is not itself a ninth fruit. | H595: Truth is necessary but not sufficient. A statement can be factually accurate and still be delivered cruelly, manipulatively, prematurely, or dominantly. An act styled as 'loving' that conceals or distorts reality fails the governing condition.
A598: ANTI-FRUIT TAXONOMY BY TYPE
A599: Not every fruit-like word is a fruit: a term may be a deficiency, an excess/counterfeit, or a direct contrary. A = {privation, distortion, excess, deficiency, counterfeit}.
A600: Fruit | B600: Deficiency | C600: Excess / counterfeit | D600: Direct contrary
A601: Love | B601: Indifference | C601: Possessiveness, enabling | D601: Hatred, exploitation
...

Sheet SI_OBJECT_TYPES
A1: EPISTEMIC OBJECT — REQUIRED CORE FIELDS
A2: Field | B2: Meaning
A3: object_id | B3: Immutable machine identity, preferably UUID/ULID
A4: human_code | B4: Stable readable code such as A0, Q-014, CLM-208, BR-031
A5: object_type | B5: Primary logical object type
A6: canonical_text | B6: Smallest complete statement or definition
A7: scope | B7: Universe, framework, model, population, time, or conditions covered
A8: modality | B8: Necessary, possible, actual, probable, conditional, normative, interrogative
A9: polarity | B9: Affirmed, denied, suspended, alternative
A10: owner_framework | B10: Framework in which the object is defined
A11: status | B11: Draft, proposed, active, contested, supported, defeated, superseded, retired
A12: created_by / created_at | B12: Authorship and time
A13: version | B13: Semantic version of this object
A14: OBJECT TYPES — CONTROLLED VOCABULARY
A15: Family | B15: Types
A16: Foundations | B16: AXIOM, CONSTITUTIVE_DISCLOSURE, PRIMITIVE, DEFINITION, DISTINCTION
A17: Inquiry | B17: QUESTION, QUESTION_FAMILY, RESPONSE, OBSERVATION
A18: Reasoning | B18: CLAIM, PREMISE, LEMMA, THEOREM, COROLLARY, DERIVATION, INFERENCE_RULE
A19: Representation | B19: MODEL, FORMAL_EXPRESSION, ANALOGY, METAPHOR, INTERPRETATION
A20: Connection | B20: BRIDGE, TRANSLATION, CORRESPONDENCE, IDENTITY_CLAIM
A21: Evaluation | B21: EVIDENCE_UNIT, PREDICTION, PROTOCOL, TEST, RESULT, FALSIFIER, DEFEATER
A22: Critique | B22: OBJECTION, COUNTEREXAMPLE, COUNTERMODEL, ALTERNATIVE_EXPLANATION, LIMITATION
A23: Synthesis | B23: LAW, PRINCIPLE, SYNTHESIS, APPLICATION
A24: The primary type answers 'what does this record do?' Secondary logical-role tags are allowed, but one primary type is mandatory in each argument context.

Sheet SI_CLASS_AXES
A1: MULTIAXIAL CLASSIFICATION — INDEPENDENT AXES
A2: Classification is stored as assignments, not hard-coded columns. One object carries multiple domains and can be reassessed without mutation. Each assignment records classifier, date, confidence, rationale, source. Conflicting assignments may coexist until adjudicated.
A3: Axis | B3: Example terms
A4: Logical role | B4: definition, axiom, theorem, model, bridge, prediction, interpretation
A5: Ontological domain | B5: mathematical, physical, informational, theological, consciousness, moral, cosmological, relational, ontological, epistemic
A6: Relation to A0 | B6: constitutive of, disclosed by, derived from, compatible with, independent of, opposed to, unassessed
A7: Ontological mode | B7: positive-prior, dependent-positive, relational, privative, corruptive, operational, representational, formal-only, empirical-candidate
A8: Warrant type | B8: axiomatic, deductive, abductive, inductive, testimonial, revelatory, phenomenological, empirical, pragmatic, analogical
A9: Formal status | B9: unformalized, notation-only, defined, derived, proven-relative-to-premises, simulated, dimensionally checked
A10: Empirical status | B10: non-empirical, operationalizable, predicted, protocol-ready, tested, replicated, disconfirmed, underdetermined
A11: Epistemic status | B11: stipulated, inferred, observed, interpreted, contested, provisionally accepted, rejected
A12: Bridge strength | B12: metaphorical, heuristic, structural analogy, homomorphism, isomorphism, causal proposal, identity claim
A13: PRIMARY + SECONDARY EXAMPLE (one object, many independent facts)
A14: primary logical role | B14: BRIDGE
A15: primary domain | B15: INFORMATIONAL
A16: secondary domains | B16: THEOLOGICAL, PHYSICAL
A17: warrant | B17: ABDUCTIVE
A18: empirical status | B18: OPERATIONALIZABLE
A19: bridge strength | B19: CAUSAL_PROPOSAL
A20: The system must never convert these independent facts into one opaque label.

Sheet SI_RELATIONS
A1: TYPED RELATIONS — THE INFERENCE GRAPH
A2: An edge is never 'just a link'; it states a relationship and requires its own provenance and warrant. The derivation subgraph must be acyclic — other relations may form cycles, but cycles cannot masquerade as proofs.
A3: Relation group | B3: Edge types
A4: Constitution | B4: CONSTITUTIVE_OF, DISCLOSES, DEFINES, HAS_PART, INSTANTIATES
A5: Inference | B5: DEPENDS_ON, DERIVED_FROM, ENTAILS, IMPLIES, COROLLARY_OF, USES_RULE
A6: Evidence | B6: SUPPORTS, WEAKENS, CONTRADICTS, UNDERDETERMINES, EXPLAINS, PREDICTS
A7: Testing | B7: TESTS, FALSIFIES_IF, CONFIRMS_IF, IMPLEMENTS_PROTOCOL, PRODUCES_RESULT
A8: Bridging | B8: MAPS_FROM, MAPS_TO, PRESERVES, LOSES, TRANSLATES, CORRESPONDS_TO
A9: Critique | B9: OBJECTS_TO, COUNTEREXAMPLE_TO, COUNTERMODEL_TO, DEFEATS, LIMITS
A10: Governance | B10: DUPLICATES, REFINES, SUPERSEDES, RETRACTS, CONFLICTS_WITH
A11: EVERY CONSEQUENTIAL EDGE RECORDS
A12: source and target object versions; direction; relation type; whether it claims necessity/sufficiency/probability/compatibility/analogy; stated warrant; supporting source spans; assumptions required; confidence and status; defeat conditions.
A13: A0 AND CONSTITUTIVE DISCLOSURE
A14: Object | B14: Type / Relation
A15: A0 | B15: AXIOM — root declaration of the Triune God
A16: Trinity | B16: CONSTITUTIVE_DISCLOSURE — CONSTITUTIVE_OF A0
A17: Being / 'I AM' | B17: CONSTITUTIVE_DISCLOSURE — CONSTITUTIVE_OF A0
A18: Truth | B18: CONSTITUTIVE_DISCLOSURE — CONSTITUTIVE_OF A0
A19: Goodness | B19: CONSTITUTIVE_DISCLOSURE — CONSTITUTIVE_OF A0
A20: Love | B20: CONSTITUTIVE_DISCLOSURE — CONSTITUTIVE_OF A0
A21: Relational distinction without division | B21: CONSTITUTIVE_DISCLOSURE — CONSTITUTIVE_OF A0
A22: Positive fruits / dispositional expressions | B22: CONSTITUTIVE_DISCLOSURE or DERIVED_EXPRESSION (as argued) — linked with explicit warrant
A23: A0 AUDIT — every proposed disclosure must answer
A24: 1 | B24: Is this constitutive, definitional, entailed, inferred, analogical, or merely associated?
A25: 2 | B25: Could A0 remain numerically the same axiom if this content were denied?
A26: 3 | B26: Is the disclosure textually declared, logically required, traditionally received, or introduced by the present model?
A27: 4 | B27: What later derivations depend on it?
A28: 5 | B28: Does moving it into or out of A0 change the theory's conclusions?

Sheet SI_SCHEMA_TABLES
A1: MINIMAL RELATIONAL IMPLEMENTATION
A2: Table | B2: Purpose | C2: Plane
A3: artifacts | B3: stable source identities | C3: Provenance
A4: artifact_versions | B4: immutable source versions and hashes | C4: Provenance
A5: source_spans | B5: precise source locators | C5: Provenance
A6: epistemic_objects | B6: universal typed object registry | C6: Semantic
A7: object_versions | B7: canonical text and scoped semantic versions | C7: Semantic
A8: object_occurrences | B8: object-to-source-span links | C8: Semantic
A9: relation_types | B9: controlled edge vocabulary | C9: Inferential
A10: relations | B10: versioned, warranted edges | C10: Inferential
A11: classification_axes | B11: independent dimensions | C11: Semantic
A12: classification_terms | B12: controlled values within axes | C12: Semantic
A13: classification_assignments | B13: multivalued, assessed classifications | C13: Semantic
... A28: change_events | B28: audit trail and supersession decisions | C28: Governance
A29: Use JSONB only for genuinely extensible secondary metadata. Identities, types, relations, statuses, provenance, and critical evaluation fields must remain queryable and constrained.

Sheet SI_VALIDATION
A1: VALIDATION RULES — reject or flag
A2: 1 | B2: a claim with no canonical text or scope
A3: 2 | B3: an evidence citation with no retrievable source locator
A4: 3 | B4: a derivation cycle
A5: 4 | B5: a cross-domain edge lacking a bridge dossier
A6: 5 | B6: a theorem lacking explicit premises
A7: 6 | B7: an empirical conclusion supported only by notation
A8: 7 | B8: a 'proven' status without a declared proof system or protocol
A9: 8 | B9: a question whose wording contains its expected answer
A10: 9 | B10: a result record that contains interpretation but no raw observation link
A11: 10 | B11: a constitutive disclosure treated as an independent axiom without adjudication
A12: 11 | B12: a new A0 disclosure with no semantic-addition audit
A13: 12 | B13: a classification that combines logical role and domain into one untraceable label
... A16: 15 | B16: a bridge based only on lexical similarity
A17: TEST CHAIN — each stage is a separate object
A18: CLAIM → PREDICTION → OPERATIONALIZATION → PROTOCOL → TEST RUN → RESULT → INTERPRETATION → ASSESSMENT
A19: DEFEAT CONDITIONS — every load-bearing object must declare relevant forms ('N/A' only with a reason)
A20: logical contradiction • countermodel • failed entailment • empirical falsifier • unsuccessful replication • superior alternative explanation • category error • bridge failure • source/provenance failure • scope violation • semantic equivocation
A22: MIGRATION FROM EXISTING CORPUS
A23: Phase 1 — Freeze & register sources | B23: Hash every artifact version. Preserve filenames and existing codes as aliases. Do not reorganize content during registration.
A24: Phase 2 — Extract without adjudicating | B24: Segment into candidate questions, declarations, definitions, claims, equations, bridges, evidence units, predictions, objections, limitations. Retain verbatim spans.
A25: Phase 3 — Normalize objects | B25: Merge true duplicates preserving occurrences. Split compound claims. Assign stable readable codes independent of file order.
A26: Phase 4 — Reconstruct A0 | B26: Register A0 once. Classify candidate content as constitutive disclosure, definition, entailment, inference, or later association. Record disagreements rather than resolving by import order.
A27: Phase 5 — Build dependency graph | B27: Add explicit edges, then identify unsupported transitions, circular derivations, hidden premises, load-bearing bridges.
A28: Phase 6 — Attach evaluation | B28: Connect evidence, formal expressions, tests, countermodels, limitations, defeat conditions.
A29: Phase 7 — Run neutral inquiry | B29: Only after slots and validation rules are frozen: finalize and execute the unbiased question canon. Prevents the desired answer from redesigning the questions after the fact.
A30: FIVE DECISIONS REQUIRED BEFORE V1 IS FROZEN (governance, not software defaults)
A31: 1. A0 disclosure boundary | B31: Which properties are strictly constitutive, and which are derived expressions?
A32: 2. Canonical codes | B32: Whether readable identifiers follow families such as AX, DSC, Q, CLM, BR, EVD, TST.
